<?xml version="1.0"?>

<robot xmlns:xacro="http://www.ros.org/wiki/xacro" name="arduinobot">
    <!-- variables -->
    <xacro:property name="PI" value="3.14159265359" />
    <xacro:property name="velocity" value="10.0" />
    <xacro:property name="effort" value="30.0" />

    <!-- links -->

    <link name="world" />

    <link name="base_link">
        <visual>
            <origin xyz="-0.5 -0.5 0" rpy="0 0 0" />
            <geometry>
                <mesh filename="package://arduinobot_description/meshes/basement.STL"
                    scale="0.01 0.01 0.01" />
            </geometry>
        </visual>
        <collision>
            <origin xyz="-0.5 -0.5 0" rpy="0 0 0" />
            <geometry>
                <mesh filename="package://arduinobot_description/meshes/basement.STL"
                    scale="0.01 0.01 0.01" />
            </geometry>
        </collision>
    </link>

    <link name="base_plate_link">
        <visual>
            <origin xyz="-0.39 -0.39 -0.56" rpy="0 0 0" />
            <geometry>
                <mesh filename="package://arduinobot_description/meshes/base_plate.STL"
                    scale="0.01 0.01 0.01" />
            </geometry>
        </visual>
        
    </link>

    <link name="forward_drive_arm_link">
        <visual>
            <origin xyz="0.19 0.06 -0.08" rpy="0 -${PI/2} ${PI/2}" />
            <geometry>
                <mesh filename="package://arduinobot_description/meshes/forward_drive_arm.STL"
                    scale="0.01 0.01 0.01" />
            </geometry>
        </visual>
    </link>

    <link name="horizontal_arm_link">
        <visual>
            <origin xyz="-0.03 -0.4 -0.06" rpy="${PI/2} 0 ${PI/2}" />
            <geometry>
                <mesh filename="package://arduinobot_description/meshes/horizontal_arm.STL"
                    scale="0.01 0.01 0.01" />
            </geometry>
        </visual>
    </link>

    <link name="claw_support_link">
        <visual>
            <origin xyz="0 -0.05 -0.15" rpy="0 0 ${PI/2}" />
            <geometry>
                <mesh filename="package://arduinobot_description/meshes/claw_support.STL"
                    scale="0.01 0.01 0.01" />
            </geometry>
        </visual>
    </link>

    <link name="gripper_right_link">
        <visual>
            <origin xyz="-0.1 0.5 -0.1" rpy="0 0 -${PI/2}" />
            <geometry>
                <mesh filename="package://arduinobot_description/meshes/right_finger.STL"
                    scale="0.01 0.01 0.01" />
            </geometry>
        </visual>
    </link>

    <link name="gripper_left_link">
        <visual>
            <origin xyz="-0.04 0.5 -0.1" rpy="0 0 -${PI/2}" />
            <geometry>
                <mesh filename="package://arduinobot_description/meshes/left_finger.STL"
                    scale="0.01 0.01 0.01" />
            </geometry>
        </visual>
    </link>


    <!-- joints -->

    <joint name="virtual_joint" type="fixed">
        <parent link="world" />
        <child link="base_link" />
        <origin xyz="0 0 0" rpy="0 0 0" />
    </joint>

    <joint name="base_base_plate_joint_1" type="revolute">
        <parent link="base_link" />
        <child link="base_plate_link" />
        <origin xyz="0 0 0.307" rpy="0 0 0" />
        <axis xyz="0 0 1" />
        <limit lower="-${PI/2}" upper="${PI/2}" effort="${effort}" velocity="${velocity}" />
    </joint>

    <joint name="base_plate_forward_drive_arm_joint_2" type="revolute">
        <parent link="base_plate_link" />
        <child link="forward_drive_arm_link" />
        <origin xyz="-0.02 0 0.35" rpy="0 0 0" />
        <axis xyz="1 0 0" />
        <limit lower="-${PI/2}" upper="${PI/2}" effort="${effort}" velocity="${velocity}" />
    </joint>

    <joint name="forward_drive_arm_horizontal_arm_joint_3" type="revolute">
        <parent link="forward_drive_arm_link" />
        <child link="horizontal_arm_link" />
        <origin xyz="0 0 0.8" rpy="0 0 0" />
        <axis xyz="1 0 0" />
        <limit lower="-${PI/2}" upper="${PI/2}" effort="${effort}" velocity="${velocity}" />
    </joint>

    <joint name="horizontal_arm_claw_support_joint" type="fixed">
        <parent link="horizontal_arm_link" />
        <child link="claw_support_link" />
        <origin xyz="0 0.82 0" rpy="0 0 0" />
    </joint>

    <joint name="claw_support_gripper_right_joint_4" type="revolute">
        <parent link="claw_support_link" />
        <child link="gripper_right_link" />
        <origin xyz="-0.04 0.13 -0.1" rpy="0 0 0" />
        <axis xyz="0 0 1" />
        <limit lower="-${PI/2}" upper="0.0" effort="${effort}" velocity="${velocity}" />
    </joint>

    <joint name="claw_support_gripper_left_joint_5" type="revolute">
        <parent link="claw_support_link" />
        <child link="gripper_left_link" />
        <origin xyz="-0.22 0.13 -0.1" rpy="0 0 0" />
        <axis xyz="0 0 1" />
        <limit lower="0.0" upper="${PI/2}" effort="${effort}" velocity="${velocity}" />
        <mimic joint="claw_support_gripper_right_joint_4" multiplier="-1" offset="0" />
    </joint>

</robot>